Workbook

Sheet Dane wejściowe
A1: ⚡ KALKULATOR ROZLICZENIA PRĄDU – Rodzina A / Rodzina B
A2: Wypełniaj tylko pola niebieskie. Pola szare są obliczane automatycznie.
A4: 1 │ DANE Z FAKTURY
B5: Pozycja | C5: Wartość netto (zł) | D5: VAT (%) | E5: Kwota VAT (zł) | F5: Wartość brutto (zł)
B6: Energia elektryczna czynna (zmienna) | C6: 210.5 | D6: 23 | E6: =C6*D6/100 -> 48.415 | F6: =C6+E6 -> 258.915
B7: Składnik zmienny stawki sieciowej | C7: 98.3 | D7: 23 | E7: =C7*D7/100 -> 22.609 | F7: =C7+E7 -> 120.909
B8: Stawka jakościowa | C8: 14.2 | D8: 23 | E8: =C8*D8/100 -> 3.266 | F8: =C8+E8 -> 17.466
B9: Opłata OZE | C9: 3.1 | D9: 23 | E9: =C9*D9/100 -> 0.713 | F9: =C9+E9 -> 3.813
B10: Opłata kogeneracyjna | C10: 1.28 | D10: 23 | E10: =C10*D10/100 -> 0.2944 | F10: =C10+E10 -> 1.5744
B11: Opłata Handlowa (stała) | C11: 15 | D11: 23 | E11: =C11*D11/100 -> 3.45 | F11: =C11+E11 -> 18.45
B12: Opłata mocowa (stała) | C12: 20 | D12: 23 | E12: =C12*D12/100 -> 4.6 | F12: =C12+E12 -> 24.6
B13: Abonament / stawka opłaty abonamentowej | C13: 4.2 | D13: 23 | E13: =C13*D13/100 -> 0.966 | F13: =C13+E13 -> 5.166
B14: Składnik stały stawki sieciowej | C14: 9.5 | D14: 23 | E14: =C14*D14/100 -> 2.185 | F14: =C14+E14 -> 11.685
B15: Stawka opłaty przejściowej | C15: 0 | D15: 23 | E15: =C15*D15/100 -> 0 | F15: =C15+E15 -> 0
B16: RAZEM FAKTURA | C16: =SUM(C6:C15) -> 376.08 | E16: =SUM(E6:E15) -> 86.4984 | F16: =SUM(F6:F15) -> 462.5784
A18: 2 │ GŁÓWNY LICZNIK (odczyt ze zlecenia)
B19: Okres rozliczeniowy – OD | C19: 46023
B20: Okres rozliczeniowy – DO | C20: 46053
B21: Liczba dni okresu (obliczona) | C21: =IF(AND(ISNUMBER(C20),ISNUMBER(C19)),C20-C19,"?") -> 30
B22: Łączne zużycie wg faktury (kWh) | C22: 480
B23: ⚙️ Pierwszy miesiąc – wyłącz korektę proporcjonalną? | C23: NIE | D23: ← wybierz "TAK" tylko dla pierwszego okresu (brak wcześniejszego, zsynchronizowanego odczytu)
A24: 3 │ PODLICZNIK – RODZINA B
B25: Pole | C25: Odczyt / Data | D25: Komentarz
B26: Data odczytu POPRZEDNIEGO | C26: 46023 | D26: ← powinna pokrywać się z początkiem okresu faktury
B27: Stan licznika POPRZEDNIEGO (kWh) | C27: 1500
B28: Data odczytu BIEŻĄCEGO | C28: 46053 | D28: ← powinna pokrywać się z końcem okresu faktury
B29: Stan licznika BIEŻĄCEGO (kWh) | C29: 1580
B30: Liczba dni pomiaru B | C30: =IF(AND(ISNUMBER(C28),ISNUMBER(C26)),C28-C26,"?") -> 30
B31: Zużycie zmierzone B (kWh) | C31: =C29-C27 -> 80
B32: Korekta proporcjonalna B (do okresu faktury) | C32: =IF(C23="TAK (pierwszy okres)",C31,IF(AND(ISNUMBER(C30),C30>0,ISNUMBER(C21)),C31*C21/C30,C31)) -> 80 | D32: ← jeśli daty B nie pokrywają się idealnie z fakturą, zużycie jest proporcjonalnie przeliczane
A34: 4 │ PODLICZNIK – PIEC / BOJLER (wspólny, dzielony 50/50)
B36: Data odczytu POPRZEDNIEGO | C36: 46036 | D36: ← powinna pokrywać się z początkiem okresu faktury
B37: Stan licznika POPRZEDNIEGO (kWh) | C37: 300
B38: Data odczytu BIEŻĄCEGO | C38: 46053 | D38: ← powinna pokrywać się z końcem okresu faktury
B39: Stan licznika BIEŻĄCEGO (kWh) | C39: 445
B40: Liczba dni pomiaru bojlera | C40: =IF(AND(ISNUMBER(C38),ISNUMBER(C36)),C38-C36,"?") -> 17
B41: Zużycie zmierzone bojler (kWh) | C41: =C39-C37 -> 145
B42: Korekta proporcjonalna bojler (do okresu faktury) | C42: =IF(C23="TAK (pierwszy okres)",C41,IF(AND(ISNUMBER(C40),C40>0,ISNUMBER(C21)),C41*C21/C40,C41)) -> 255.88235 | D42: ← proporcjonalne przeliczenie analogicznie jak dla B
A46: LEGENDA / INSTRUKCJA WYPEŁNIANIA
B47: 🔵 Komórki niebieskie | C47: Dane do wpisania ręcznie (z faktury lub odczytu licznika)
...

Sheet Obliczenia
A1: ⚡ OBLICZENIA PODZIAŁU KOSZTÓW
A3: A │ ZUŻYCIA kWh
B4: Składnik | C4: kWh | D4: Uwagi
B5: Łącznie wg faktury | C5: ='Dane wejściowe'!C22 -> 480
B6: Rodzina B – zmierzone (skorygowane) | C6: ='Dane wejściowe'!C32 -> 80
B7: Piec/Bojler – zmierzone (skorygowane) | C7: ='Dane wejściowe'!C42 -> 255.88235
B8: Rodzina A – własne (obliczone) | C8: =C5-C6-C7 -> 144.11765 | D8: Reszta po odjęciu B i bojlera
B9: Piec/Bojler – udział A (50%) | C9: =C7/2 -> 127.94118 | D9: 50% bojlera
B10: Piec/Bojler – udział B (50%) | C10: =C7/2 -> 127.94118 | D10: 50% bojlera
B11: RAZEM Rodzina A (własne + bojler 50%) | C11: =C8+C9 -> 272.05882
B12: RAZEM Rodzina B (własne + bojler 50%) | C12: =C6+C10 -> 207.94118
B13: Kontrola (A+B powinno = łącznie) | C13: =C11+C12 -> 480 | D13: Powinno równać się wierszowi "Łącznie wg faktury"
A16: B │ STAWKI
B17: Stawka | C17: Wartość | D17: Opis
B18: Stawka zmienna NETTO (zł/kWh) | C18: =IF('Dane wejściowe'!C22>0,SUM('Dane wejściowe'!C6:C10)/'Dane wejściowe'!C22,0) -> 0.68204167
B19: Stawka zmienna BRUTTO (zł/kWh) | C19: =IF('Dane wejściowe'!C22>0,SUM('Dane wejściowe'!F6:F10)/'Dane wejściowe'!C22,0) -> 0.83891125
B20: Koszty stałe BRUTTO łącznie (zł) | C20: =SUM('Dane wejściowe'!F11:F15) -> 59.901
B21: Koszty stałe BRUTTO na rodzinę (zł / 2) | C21: =C20/2 -> 29.9505
A23: C │ WYNIK KOŃCOWY
B24: Składnik kosztu | C24: Rodzina A (zł) | D24: Rodzina B (zł)
B25: Koszty zmienne (zużycie × stawka brutto) | C25: =C11*C19 -> 228.23321 | D25: =C12*C19 -> 174.44419
B26: Koszty stałe (50% / 50%) | C26: =C21 -> 29.9505 | D26: =C21 -> 29.9505
B27: DO ZAPŁATY | C27: =SUM(C25:C26) -> 258.18371 | D27: =SUM(D25:D26) -> 204.39469
B28: Kontrola (A+B = suma faktury) | C28: =C27+D27 -> 462.5784 | D28: ='Dane wejściowe'!F16 -> 462.5784 | E28: =IF(ABS(C28-D28)<0.02,"✅ OK","⚠️ SPRAWDŹ") -> ✅ OK
A30: D │ SZCZEGÓŁY PODZIAŁU kWh | O30: 264.98
B31: Składnik | C31: Rodzina A | D31: Rodzina B | E31: Razem
B32: Zużycie własne | C32: =C8 -> 144.11765 | D32: =C6 -> 80 | E32: =C8+C6 -> 224.11765
B33: Udział w bojlerze (50%) | C33: =C9 -> 127.94118 | D33: =C10 -> 127.94118 | E33: =C9+C10 -> 255.88235
B34: RAZEM | C34: =C11 -> 272.05882 | D34: =C12 -> 207.94118 | E34: =C11+C12 -> 480
A36: E │ OSTRZEŻENIA O SYNCHRONIZACJI DAT
B37: Licznik B – data OD vs faktura OD | C37: =IF(AND(ISNUMBER('Dane wejściowe'!C26),ISNUMBER('Dane wejściowe'!C19)),IF(ABS('Dane wejściowe'!C26-'Dane wejściowe'!C19)<=1,"✅ Zsynchronizowany","⚠️ Różnica: "&ABS('Dane wejściowe'!C26-'Dane wejściowe'!C19)&" dni – stosowana korekta proporcjonalna"),"Brak daty") -> ✅ Zsynchronizowany
B38: Licznik B – data DO vs faktura DO | C38: =IF(AND(ISNUMBER('Dane wejściowe'!C28),ISNUMBER('Dane wejściowe'!C20)),IF(ABS('Dane wejściowe'!C28-'Dane wejściowe'!C20)<=1,"✅ Zsynchronizowany","⚠️ Różnica: "&ABS('Dane wejściowe'!C28-'Dane wejściowe'!C20)&" dni – stosowana korekta proporcjonalna"),"Brak daty") -> ✅ Zsynchronizowany
B39: Bojler – data OD vs faktura OD | C39: =IF(AND(ISNUMBER('Dane wejściowe'!C36),ISNUMBER('Dane wejściowe'!C19)),IF(ABS('Dane wejściowe'!C36-'Dane wejściowe'!C19)<=1,"✅ Zsynchronizowany","⚠️ Różnica: "&ABS('Dane wejściowe'!C36-'Dane wejściowe'!C19)&" dni – stosowana korekta proporcjonalna"),"Brak daty") -> ⚠️ Różnica: 13 dni – stosowana korekta proporcjonalna
B40: Bojler – data DO vs faktura DO | C40: =IF(AND(ISNUMBER('Dane wejściowe'!C38),ISNUMBER('Dane wejściowe'!C20)),IF(ABS('Dane wejściowe'!C38-'Dane wejściowe'!C20)<=1,"✅ Zsynchronizowany","⚠️ Różnica: "&ABS('Dane wejściowe'!C38-'Dane wejściowe'!C20)&" dni – stosowana korekta proporcjonalna"),"Brak daty") -> ✅ Zsynchronizowany

Sheet Historia miesięczna
A1: 📅 HISTORIA MIESIĘCZNA ROZLICZEŃ
A2: Wiersz "Bieżący miesiąc" aktualizuje się automatycznie. Po zakończeniu okresu skopiuj go jako wartości do archiwum (wiersz 8+), a następnie wprowadź dane nowego miesiąca w arkuszu "Dane wejściowe".
B4: Miesiąc (faktura DO) | C4: kWh faktura | D4: kWh Rodz. B | E4: kWh bojler | F4: kWh Rodz. A | G4: Faktura BRUTTO (zł) | H4: Do zapłaty Rodz. A (zł) | I4: Do zapłaty Rodz. B (zł) | J4: Kontrola A+B (zł) | K4: kWh A (z bojlerem) | L4: kWh B (z bojlerem) | M4: Stawka zł/kWh brutto | N4: Koszty stałe (zł)
A5: 🔄 BIEŻĄCY MIESIĄC (aktualizuje się automatycznie z arkusza Obliczenia)
B6: ='Dane wejściowe'!C20 -> 46053 | C6: ='Dane wejściowe'!C22 -> 480 | D6: =Obliczenia!C6 -> 80 | E6: =Obliczenia!C7 -> 255.88235 | F6: =Obliczenia!C8 -> 144.11765 | G6: ='Dane wejściowe'!F16 -> 462.5784 | H6: =Obliczenia!C27 -> 258.18371 | I6: =Obliczenia!D27 -> 204.39469 | J6: =H6+I6 -> 462.5784 | K6: =Obliczenia!C11 -> 272.05882 | L6: =Obliczenia!C12 -> 207.94118 | M6: =Obliczenia!C19 -> 0.83891125 | N6: =Obliczenia!C20 -> 59.901
A7: 📋 ARCHIWUM – aby zapisać bieżący miesiąc: zaznacz wiersz 6 → Kopiuj → kliknij pierwszy pusty wiersz poniżej → Wklej specjalnie → Tylko wartości
B8: 46022 | C8: 452 | D8: 76 | E8: 198 | F8: 178 | G8: 415.6 | H8: 268.17 | I8: 181.97 | J8: 483.4638 | K8: 243.74 | L8: 180.26 | M8: 0.97268632 | N8: 71.0448
B9: 46053 | C9: 480 | D9: 80 | E9: 255.88 | F9: 144.12 | G9: 470.3 | H9: 268.07 | I9: 212.93 | J9: 566.1567 | K9: 257 | L9: 252 | M9: 0.97271493 | N9: 71.0448
F10: =C10-D10-E10 -> 0 | J10: =H10+I10 -> 0 | K10: =IF(C10="","",F10+E10/2) | L10: =IF(C10="","",D10+E10/2) | M10: =IF(AND(ISNUMBER(C10),C10>0,ISNUMBER(G10),ISNUMBER(N10)),(H10+I10-N10)/C10,"")
F11: =C11-D11-E11 -> 0 | J11: =H11+I11 -> 0 | K11: =IF(C11="","",F11+E11/2) | L11: =IF(C11="","",D11+E11/2) | M11: =IF(AND(ISNUMBER(C11),C11>0,ISNUMBER(G11),ISNUMBER(N11)),(H11+I11-N11)/C11,"")
F12: =C12-D12-E12 -> 0 | J12: =H12+I12 -> 0 | K12: =IF(C12="","",F12+E12/2) | L12: =IF(C12="","",D12+E12/2) | M12: =IF(AND(ISNUMBER(C12),C12>0,ISNUMBER(G12),ISNUMBER(N12)),(H12+I12-N12)/C12,"")
F13: =C13-D13-E13 -> 0 | J13: =H13+I13 -> 0 | K13: =IF(C13="","",F13+E13/2) | L13: =IF(C13="","",D13+E13/2) | M13: =IF(AND(ISNUMBER(C13),C13>0,ISNUMBER(G13),ISNUMBER(N13)),(H13+I13-N13)/C13,"")
F14: =C14-D14-E14 -> 0 | J14: =H14+I14 -> 0 | K14: =IF(C14="","",F14+E14/2) | L14: =IF(C14="","",D14+E14/2) | M14: =IF(AND(ISNUMBER(C14),C14>0,ISNUMBER(G14),ISNUMBER(N14)),(H14+I14-N14)/C14,"")
F15: =C15-D15-E15 -> 0 | J15: =H15+I15 -> 0 | K15: =IF(C15="","",F15+E15/2) | L15: =IF(C15="","",D15+E15/2) | M15: =IF(AND(ISNUMBER(C15),C15>0,ISNUMBER(G15),ISNUMBER(N15)),(H15+I15-N15)/C15,"")
F16: =C16-D16-E16 -> 0 | J16: =H16+I16 -> 0 | K16: =IF(C16="","",F16+E16/2) | L16: =IF(C16="","",D16+E16/2) | M16: =IF(AND(ISNUMBER(C16),C16>0,ISNUMBER(G16),ISNUMBER(N16)),(H16+I16-N16)/C16,"")
F17: =C17-D17-E17 -> 0 | J17: =H17+I17 -> 0 | K17: =IF(C17="","",F17+E17/2) | L17: =IF(C17="","",D17+E17/2) | M17: =IF(AND(ISNUMBER(C17),C17>0,ISNUMBER(G17),ISNUMBER(N17)),(H17+I17-N17)/C17,"")
F18: =C18-D18-E18 -> 0 | J18: =H18+I18 -> 0 | K18: =IF(C18="","",F18+E18/2) | L18: =IF(C18="","",D18+E18/2) | M18: =IF(AND(ISNUMBER(C18),C18>0,ISNUMBER(G18),ISNUMBER(N18)),(H18+I18-N18)/C18,"")
F19: =C19-D19-E19 -> 0 | J19: =H19+I19 -> 0 | K19: =IF(C19="","",F19+E19/2) | L19: =IF(C19="","",D19+E19/2) | M19: =IF(AND(ISNUMBER(C19),C19>0,ISNUMBER(G19),ISNUMBER(N19)),(H19+I19-N19)/C19,"")
F20: =C20-D20-E20 -> 0 | J20: =H20+I20 -> 0 | K20: =IF(C20="","",F20+E20/2) | L20: =IF(C20="","",D20+E20/2) | M20: =IF(AND(ISNUMBER(C20),C20>0,ISNUMBER(G20),ISNUMBER(N20)),(H20+I20-N20)/C20,"")
F21: =C21-D21-E21 -> 0 | J21: =H21+I21 -> 0 | K21: =IF(C21="","",F21+E21/2) | L21: =IF(C21="","",D21+E21/2) | M21: =IF(AND(ISNUMBER(C21),C21>0,ISNUMBER(G21),ISNUMBER(N21)),(H21+I21-N21)/C21,"")
... F31: =C31-D31-E31 -> 0 | J31: =H31+I31 -> 0 | K31: =IF(C31="","",F31+E31/2) | L31: =IF(C31="","",D31+E31/2) | M31: =IF(AND(ISNUMBER(C31),C31>0,ISNUMBER(G31),ISNUMBER(N31)),(H31+I31-N31)/C31,"")

Sheet 📊 Dashboard
A1: ⚡ DASHBOARD ROZLICZENIA PRĄDU – Rodzina A / Rodzina B
A2: 🔄 Dane aktualizują się automatycznie z arkuszy "Obliczenia" i "Historia miesięczna" | Liczba miesięcy w wykresach: zmień w arkuszu "Dane_Wykres" komórka B1
B4: BIEŻĄCA FAKTURA | G4: RODZINA A – płaci | L4: RODZINA B – płaci | Q4: ŁĄCZNIE kWh | V4: STAWKA zł/kWh brutto
B5: =Obliczenia!C28 -> 462.5784 | G5: =Obliczenia!C27 -> 258.18371 | L5: =Obliczenia!D27 -> 204.39469 | Q5: ='Dane wejściowe'!C22 -> 480 | V5: =Obliczenia!C19 -> 0.83891125
B8: bieżący okres | G8: bieżący miesiąc | L8: bieżący miesiąc | Q8: bieżący okres | V8: bieżący okres
B10: 📊 Koszty miesięczne – Rodzina A vs B | O10: 📊 Zużycie kWh – podział miesięczny
B30: 📊 Trend stawki jednostkowej (zł/kWh brutto) | O30: 📊 Porównanie udziału kosztów A vs B (%)
B44: 📋 Bieżący miesiąc – szczegółowy podział
B45: Składnik | C45: kWh | D45: Udział % | E45: Koszt (zł) | F45: Udział %
B46: Rodzina A | D46: =Obliczenia!C11 -> 272.05882 | F46: =IFERROR(Obliczenia!C11/'Dane wejściowe'!C22,0) -> 0.56678922 | H46: =Obliczenia!C27 -> 258.18371 | J46: =IFERROR(Obliczenia!C27/Obliczenia!C28,0) -> 0.55814043
B47: Rodzina B | D47: =Obliczenia!C12 -> 207.94118 | F47: =IFERROR(Obliczenia!C12/'Dane wejściowe'!C22,0) -> 0.43321078 | H47: =Obliczenia!D27 -> 204.39469 | J47: =IFERROR(Obliczenia!D27/Obliczenia!C28,0) -> 0.44185957
B48: Bojler/Piec | D48: ='Dane wejściowe'!C42 -> 255.88235 | F48: =IFERROR('Dane wejściowe'!C42/'Dane wejściowe'!C22,0) -> 0.53308824 | H48: =IFERROR('Dane wejściowe'!C42*Obliczenia!C19,0) -> 214.66258 | J48: =IFERROR('Dane wejściowe'!C42*Obliczenia!C19/Obliczenia!C28,0) -> 0.46405665
B49: RAZEM | D49: ='Dane wejściowe'!C22 -> 480 | F49: 100% | H49: =Obliczenia!C28 -> 462.5784 | J49: 100%
B50: 📋 Statystyki historyczne (archiwum)
B51: Wskaźnik | E51: Rodzina A | G51: Rodzina B | I51: Razem | K51: Uwagi
B52: Średnia płatność (zł) | E52: =IFERROR(AVERAGEIF('Historia miesięczna'!H8:H31, ">0", 'Historia miesięczna'!H8:H31), "-") -> 268.12 | G52: =IFERROR(AVERAGEIF('Historia miesięczna'!I8:I31, ">0", 'Historia miesięczna'!I8:I31), "-") -> 197.45 | I52: =IFERROR(AVERAGEIF('Historia miesięczna'!G8:G31, ">0", 'Historia miesięczna'!G8:G31), "-") -> 442.95 | K52: z dostępnych miesięcy w archiwum
B53: Maks. płatność (zł) | E53: =IFERROR(_xludf.maxifs('Historia miesięczna'!H8:H31, 'Historia miesięczna'!H8:H31, ">0"), "-") -> - | G53: =IFERROR(_xludf.maxifs('Historia miesięczna'!I8:I31, 'Historia miesięczna'!I8:I31, ">0"), "-") -> - | I53: =IFERROR(_xludf.maxifs('Historia miesięczna'!G8:G31, 'Historia miesięczna'!G8:G31, ">0"), "-") -> -
B54: Min. płatność (zł) | E54: =IFERROR(_xludf.minifs('Historia miesięczna'!H8:H31, 'Historia miesięczna'!H8:H31, ">0"), "-") -> - | G54: =IFERROR(_xludf.minifs('Historia miesięczna'!I8:I31, 'Historia miesięczna'!I8:I31, ">0"), "-") -> - | I54: =IFERROR(_xludf.minifs('Historia miesięczna'!G8:G31, 'Historia miesięczna'!G8:G31, ">0"), "-") -> -
B55: Łączne zużycie kWh (suma) | E55: =IFERROR(SUMIF('Historia miesięczna'!K8:K31, ">0", 'Historia miesięczna'!K8:K31), "-") -> 500.74 | G55: =IFERROR(SUMIF('Historia miesięczna'!L8:L31, ">0", 'Historia miesięczna'!L8:L31), "-") -> 432.26 | I55: =IFERROR(SUMIF('Historia miesięczna'!C8:C31, ">0", 'Historia miesięczna'!C8:C31), "-") -> 932 | K55: A i B = z udziałem w bojlerze
B56: Śr. miesięczne kWh | E56: =IFERROR(AVERAGEIF('Historia miesięczna'!K8:K31, ">0", 'Historia miesięczna'!K8:K31), "-") -> 250.37 | G56: =IFERROR(AVERAGEIF('Historia miesięczna'!L8:L31, ">0", 'Historia miesięczna'!L8:L31), "-") -> 216.13 | I56: =IFERROR(AVERAGEIF('Historia miesięczna'!C8:C31, ">0", 'Historia miesięczna'!C8:C31), "-") -> 466
B57: Łączna suma zapłacona (zł) | E57: =IFERROR(SUMIF('Historia miesięczna'!H8:H31, ">0", 'Historia miesięczna'!H8:H31), "-") -> 536.24 | G57: =IFERROR(SUMIF('Historia miesięczna'!I8:I31, ">0", 'Historia miesięczna'!I8:I31), "-") -> 394.9 | I57: =IFERROR(SUMIF('Historia miesięczna'!G8:G31, ">0", 'Historia miesięczna'!G8:G31), "-") -> 885.9 | K57: suma wszystkich archiwizowanych miesięcy
B58: Liczba zarchiwizowanych miesięcy | E58: =COUNTA('Historia miesięczna'!H8:H31) -> 2 | G58: =COUNTA('Historia miesięczna'!I8:I31) -> 2 | I58: =COUNTA('Historia miesięczna'!G8:G31) -> 2

Sheet Dane_Wykres
A1: Pokaż ostatnie N miesięcy (Dashboard): | B1: 6
A3: # | B3: Miesiąc | C3: kWh Razem | D3: kWh A | E3: kWh B | F3: kWh Bojler | G3: Faktura (zł) | H3: Koszt A (zł) | I3: Koszt B (zł) | J3: Stawka zł/kWh
A4: 1 | B4: =IF(1<=MIN($B$1,COUNTA('Historia miesięczna'!B8:B31)),INDEX('Historia miesięczna'!B8:B31,MAX(0,COUNTA('Historia miesięczna'!B8:B31)-MIN($B$1,COUNTA('Historia miesięczna'!B8:B31)))+1),"") -> 46022 | C4: =IF(1<=MIN($B$1,COUNTA('Historia miesięczna'!B8:B31)),IFERROR(INDEX('Historia miesięczna'!C8:C31,MAX(0,COUNTA('Historia miesięczna'!B8:B31)-MIN($B$1,COUNTA('Historia miesięczna'!B8:B31)))+1),0),"") -> 452 | D4: =IF(1<=MIN($B$1,COUNTA('Historia miesięczna'!B8:B31)),IFERROR(INDEX('Historia miesięczna'!F8:F31,MAX(0,COUNTA('Historia miesięczna'!B8:B31)-MIN($B$1,COUNTA('Historia miesięczna'!B8:B31)))+1),0),"") -> 178 | E4: =IF(1<=MIN($B$1,COUNTA('Historia miesięczna'!B8:B31)),IFERROR(INDEX('Historia miesięczna'!D8:D31,MAX(0,COUNTA('Historia miesięczna'!B8:B31)-MIN($B$1,COUNTA('Historia miesięczna'!B8:B31)))+1),0),"") -> 76 | F4: =IF(1<=MIN($B$1,COUNTA('Historia miesięczna'!B8:B31)),IFERROR(INDEX('Historia miesięczna'!E8:E31,MAX(0,COUNTA('Historia miesięczna'!B8:B31)-MIN($B$1,COUNTA('Historia miesięczna'!B8:B31)))+1),0),"") -> 198 | G4: =IF(1<=MIN($B$1,COUNTA('Historia miesięczna'!B8:B31)),IFERROR(INDEX('Historia miesięczna'!G8:G31,MAX(0,COUNTA('Historia miesięczna'!B8:B31)-MIN($B$1,COUNTA('Historia miesięczna'!B8:B31)))+1),0),"") -> 415.6 | H4: =IF(1<=MIN($B$1,COUNTA('Historia miesięczna'!B8:B31)),IFERROR(INDEX('Historia miesięczna'!H8:H31,MAX(0,COUNTA('Historia miesięczna'!B8:B31)-MIN($B$1,COUNTA('Historia miesięczna'!B8:B31)))+1),0),"") -> 268.17 | I4: =IF(1<=MIN($B$1,COUNTA('Historia miesięczna'!B8:B31)),IFERROR(INDEX('Historia miesięczna'!I8:I31,MAX(0,COUNTA('Historia miesięczna'!B8:B31)-MIN($B$1,COUNTA('Historia miesięczna'!B8:B31)))+1),0),"") -> 181.97 | J4: =IF(1<=MIN($B$1,COUNTA('Historia miesięczna'!B8:B31)),IFERROR(INDEX('Historia miesięczna'!K8:K31,MAX(0,COUNTA('Historia miesięczna'!B8:B31)-MIN($B$1,COUNTA('Historia miesięczna'!B8:B31)))+1),0),"") -> 243.74
A5: 2 | B5: =IF(2<=MIN($B$1,COUNTA('Historia miesięczna'!B8:B31)),INDEX('Historia miesięczna'!B8:B31,MAX(0,COUNTA('Historia miesięczna'!B8:B31)-MIN($B$1,COUNTA('Historia miesięczna'!B8:B31)))+2),"") -> 46053 | C5: =IF(2<=MIN($B$1,COUNTA('Historia miesięczna'!B8:B31)),IFERROR(INDEX('Historia miesięczna'!C8:C31,MAX(0,COUNTA('Historia miesięczna'!B8:B31)-MIN($B$1,COUNTA('Historia miesięczna'!B8:B31)))+2),0),"") -> 480 | D5: =IF(2<=MIN($B$1,COUNTA('Historia miesięczna'!B8:B31)),IFERROR(INDEX('Historia miesięczna'!F8:F31,MAX(0,COUNTA('Historia miesięczna'!B8:B31)-MIN($B$1,COUNTA('Historia miesięczna'!B8:B31)))+2),0),"") -> 144.12 | E5: =IF(2<=MIN($B$1,COUNTA('Historia miesięczna'!B8:B31)),IFERROR(INDEX('Historia miesięczna'!D8:D31,MAX(0,COUNTA('Historia miesięczna'!B8:B31)-MIN($B$1,COUNTA('Historia miesięczna'!B8:B31)))+2),0),"") -> 80 | F5: =IF(2<=MIN($B$1,COUNTA('Historia miesięczna'!B8:B31)),IFERROR(INDEX('Historia miesięczna'!E8:E31,MAX(0,COUNTA('Historia miesięczna'!B8:B31)-MIN($B$1,COUNTA('Historia miesięczna'!B8:B31)))+2),0),"") -> 255.88 | G5: =IF(2<=MIN($B$1,COUNTA('Historia miesięczna'!B8:B31)),IFERROR(INDEX('Historia miesięczna'!G8:G31,MAX(0,COUNTA('Historia miesięczna'!B8:B31)-MIN($B$1,COUNTA('Historia miesięczna'!B8:B31)))+2),0),"") -> 470.3 | H5: =IF(2<=MIN($B$1,COUNTA('Historia miesięczna'!B8:B31)),IFERROR(INDEX('Historia miesięczna'!H8:H31,MAX(0,COUNTA('Historia miesięczna'!B8:B31)-MIN($B$1,COUNTA('Historia miesięczna'!B8:B31)))+2),0),"") -> 268.07 | I5: =IF(2<=MIN($B$1,COUNTA('Historia miesięczna'!B8:B31)),IFERROR(INDEX('Historia miesięczna'!I8:I31,MAX(0,COUNTA('Historia miesięczna'!B8:B31)-MIN($B$1,COUNTA('Historia miesięczna'!B8:B31)))+2),0),"") -> 212.93 | J5: =IF(2<=MIN($B$1,COUNTA('Historia miesięczna'!B8:B31)),IFERROR(INDEX('Historia miesięczna'!K8:K31,MAX(0,COUNTA('Historia miesięczna'!B8:B31)-MIN($B$1,COUNTA('Historia miesięczna'!B8:B31)))+2),0),"") -> 257
A6: 3 | B6: =IF(3<=MIN($B$1,COUNTA('Historia miesięczna'!B8:B31)),INDEX('Historia miesięczna'!B8:B31,MAX(0,COUNTA('Historia miesięczna'!B8:B31)-MIN($B$1,COUNTA('Historia miesięczna'!B8:B31)))+3),"") | C6: =IF(3<=MIN($B$1,COUNTA('Historia miesięczna'!B8:B31)),IFERROR(INDEX('Historia miesięczna'!C8:C31,MAX(0,COUNTA('Historia miesięczna'!B8:B31)-MIN($B$1,COUNTA('Historia miesięczna'!B8:B31)))+3),0),"") | D6: =IF(3<=MIN($B$1,COUNTA('Historia miesięczna'!B8:B31)),IFERROR(INDEX('Historia miesięczna'!F8:F31,MAX(0,COUNTA('Historia miesięczna'!B8:B31)-MIN($B$1,COUNTA('Historia miesięczna'!B8:B31)))+3),0),"") | E6: =IF(3<=MIN($B$1,COUNTA('Historia miesięczna'!B8:B31)),IFERROR(INDEX('Historia miesięczna'!D8:D31,MAX(0,COUNTA('Historia miesięczna'!B8:B31)-MIN($B$1,COUNTA('Historia miesięczna'!B8:B31)))+3),0),"") | F6: =IF(3<=MIN($B$1,COUNTA('Historia miesięczna'!B8:B31)),IFERROR(INDEX('Historia miesięczna'!E8:E31,MAX(0,COUNTA('Historia miesięczna'!B8:B31)-MIN($B$1,COUNTA('Historia miesięczna'!B8:B31)))+3),0),"") | G6: =IF(3<=MIN($B$1,COUNTA('Historia miesięczna'!B8:B31)),IFERROR(INDEX('Historia miesięczna'!G8:G31,MAX(0,COUNTA('Historia miesięczna'!B8:B31)-MIN($B$1,COUNTA('Historia miesięczna'!B8:B31)))+3),0),"") | H6: =IF(3<=MIN($B$1,COUNTA('Historia miesięczna'!B8:B31)),IFERROR(INDEX('Historia miesięczna'!H8:H31,MAX(0,COUNTA('Historia miesięczna'!B8:B31)-MIN($B$1,COUNTA('Historia miesięczna'!B8:B31)))+3),0),"") | I6: =IF(3<=MIN($B$1,COUNTA('Historia miesięczna'!B8:B31)),IFERROR(INDEX('Historia miesięczna'!I8:I31,MAX(0,COUNTA('Historia miesięczna'!B8:B31)-MIN($B$1,COUNTA('Historia miesięczna'!B8:B31)))+3),0),"") | J6: =IF(3<=MIN($B$1,COUNTA('Historia miesięczna'!B8:B31)),IFERROR(INDEX('Historia miesięczna'!K8:K31,MAX(0,COUNTA('Historia miesięczna'!B8:B31)-MIN($B$1,COUNTA('Historia miesięczna'!B8:B31)))+3),0),"")
A7: 4 | B7: =IF(4<=MIN($B$1,COUNTA('Historia miesięczna'!B8:B31)),INDEX('Historia miesięczna'!B8:B31,MAX(0,COUNTA('Historia miesięczna'!B8:B31)-MIN($B$1,COUNTA('Historia miesięczna'!B8:B31)))+4),"") | C7: =IF(4<=MIN($B$1,COUNTA('Historia miesięczna'!B8:B31)),IFERROR(INDEX('Historia miesięczna'!C8:C31,MAX(0,COUNTA('Historia miesięczna'!B8:B31)-MIN($B$1,COUNTA('Historia miesięczna'!B8:B31)))+4),0),"") | D7: =IF(4<=MIN($B$1,COUNTA('Historia miesięczna'!B8:B31)),IFERROR(INDEX('Historia miesięczna'!F8:F31,MAX(0,COUNTA('Historia miesięczna'!B8:B31)-MIN($B$1,COUNTA('Historia miesięczna'!B8:B31)))+4),0),"") | E7: =IF(4<=MIN($B$1,COUNTA('Historia miesięczna'!B8:B31)),IFERROR(INDEX('Historia miesięczna'!D8:D31,MAX(0,COUNTA('Historia miesięczna'!B8:B31)-MIN($B$1,COUNTA('Historia miesięczna'!B8:B31)))+4),0),"") | F7: =IF(4<=MIN($B$1,COUNTA('Historia miesięczna'!B8:B31)),IFERROR(INDEX('Historia miesięczna'!E8:E31,MAX(0,COUNTA('Historia miesięczna'!B8:B31)-MIN($B$1,COUNTA('Historia miesięczna'!B8:B31)))+4),0),"") | G7: =IF(4<=MIN($B$1,COUNTA('Historia miesięczna'!B8:B31)),IFERROR(INDEX('Historia miesięczna'!G8:G31,MAX(0,COUNTA('Historia miesięczna'!B8:B31)-MIN($B$1,COUNTA('Historia miesięczna'!B8:B31)))+4),0),"") | H7: =IF(4<=MIN($B$1,COUNTA('Historia miesięczna'!B8:B31)),IFERROR(INDEX('Historia miesięczna'!H8:H31,MAX(0,COUNTA('Historia miesięczna'!B8:B31)-MIN($B$1,COUNTA('Historia miesięczna'!B8:B31)))+4),0),"") | I7: =IF(4<=MIN($B$1,COUNTA('Historia miesięczna'!B8:B31)),IFERROR(INDEX('Historia miesięczna'!I8:I31,MAX(0,COUNTA('Historia miesięczna'!B8:B31)-MIN($B$1,COUNTA('Historia miesięczna'!B8:B31)))+4),0),"") | J7: =IF(4<=MIN($B$1,COUNTA('Historia miesięczna'!B8:B31)),IFERROR(INDEX('Historia miesięczna'!K8:K31,MAX(0,COUNTA('Historia miesięczna'!B8:B31)-MIN($B$1,COUNTA('Historia miesięczna'!B8:B31)))+4),0),"")
A8: 5 | B8: =IF(5<=MIN($B$1,COUNTA('Historia miesięczna'!B8:B31)),INDEX('Historia miesięczna'!B8:B31,MAX(0,COUNTA('Historia miesięczna'!B8:B31)-MIN($B$1,COUNTA('Historia miesięczna'!B8:B31)))+5),"") | C8: =IF(5<=MIN($B$1,COUNTA('Historia miesięczna'!B8:B31)),IFERROR(INDEX('Historia miesięczna'!C8:C31,MAX(0,COUNTA('Historia miesięczna'!B8:B31)-MIN($B$1,COUNTA('Historia miesięczna'!B8:B31)))+5),0),"") | D8: =IF(5<=MIN($B$1,COUNTA('Historia miesięczna'!B8:B31)),IFERROR(INDEX('Historia miesięczna'!F8:F31,MAX(0,COUNTA('Historia miesięczna'!B8:B31)-MIN($B$1,COUNTA('Historia miesięczna'!B8:B31)))+5),0),"") | E8: =IF(5<=MIN($B$1,COUNTA('Historia miesięczna'!B8:B31)),IFERROR(INDEX('Historia miesięczna'!D8:D31,MAX(0,COUNTA('Historia miesięczna'!B8:B31)-MIN($B$1,COUNTA('Historia miesięczna'!B8:B31)))+5),0),"") | F8: =IF(5<=MIN($B$1,COUNTA('Historia miesięczna'!B8:B31)),IFERROR(INDEX('Historia miesięczna'!E8:E31,MAX(0,COUNTA('Historia miesięczna'!B8:B31)-MIN($B$1,COUNTA('Historia miesięczna'!B8:B31)))+5),0),"") | G8: =IF(5<=MIN($B$1,COUNTA('Historia miesięczna'!B8:B31)),IFERROR(INDEX('Historia miesięczna'!G8:G31,MAX(0,COUNTA('Historia miesięczna'!B8:B31)-MIN($B$1,COUNTA('Historia miesięczna'!B8:B31)))+5),0),"") | H8: =IF(5<=MIN($B$1,COUNTA('Historia miesięczna'!B8:B31)),IFERROR(INDEX('Historia miesięczna'!H8:H31,MAX(0,COUNTA('Historia miesięczna'!B8:B31)-MIN($B$1,COUNTA('Historia miesięczna'!B8:B31)))+5),0),"") | I8: =IF(5<=MIN($B$1,COUNTA('Historia miesięczna'!B8:B31)),IFERROR(INDEX('Historia miesięczna'!I8:I31,MAX(0,COUNTA('Historia miesięczna'!B8:B31)-MIN($B$1,COUNTA('Historia miesięczna'!B8:B31)))+5),0),"") | J8: =IF(5<=MIN($B$1,COUNTA('Historia miesięczna'!B8:B31)),IFERROR(INDEX('Historia miesięczna'!K8:K31,MAX(0,COUNTA('Historia miesięczna'!B8:B31)-MIN($B$1,COUNTA('Historia miesięczna'!B8:B31)))+5),0),"")
A9: 6 | B9: =IF(6<=MIN($B$1,COUNTA('Historia miesięczna'!B8:B31)),INDEX('Historia miesięczna'!B8:B31,MAX(0,COUNTA('Historia miesięczna'!B8:B31)-MIN($B$1,COUNTA('Historia miesięczna'!B8:B31)))+6),"") | C9: =IF(6<=MIN($B$1,COUNTA('Historia miesięczna'!B8:B31)),IFERROR(INDEX('Historia miesięczna'!C8:C31,MAX(0,COUNTA('Historia miesięczna'!B8:B31)-MIN($B$1,COUNTA('Historia miesięczna'!B8:B31)))+6),0),"") | D9: =IF(6<=MIN($B$1,COUNTA('Historia miesięczna'!B8:B31)),IFERROR(INDEX('Historia miesięczna'!F8:F31,MAX(0,COUNTA('Historia miesięczna'!B8:B31)-MIN($B$1,COUNTA('Historia miesięczna'!B8:B31)))+6),0),"") | E9: =IF(6<=MIN($B$1,COUNTA('Historia miesięczna'!B8:B31)),IFERROR(INDEX('Historia miesięczna'!D8:D31,MAX(0,COUNTA('Historia miesięczna'!B8:B31)-MIN($B$1,COUNTA('Historia miesięczna'!B8:B31)))+6),0),"") | F9: =IF(6<=MIN($B$1,COUNTA('Historia miesięczna'!B8:B31)),IFERROR(INDEX('Historia miesięczna'!E8:E31,MAX(0,COUNTA('Historia miesięczna'!B8:B31)-MIN($B$1,COUNTA('Historia miesięczna'!B8:B31)))+6),0),"") | G9: =IF(6<=MIN($B$1,COUNTA('Historia miesięczna'!B8:B31)),IFERROR(INDEX('Historia miesięczna'!G8:G31,MAX(0,COUNTA('Historia miesięczna'!B8:B31)-MIN($B$1,COUNTA('Historia miesięczna'!B8:B31)))+6),0),"") | H9: =IF(6<=MIN($B$1,COUNTA('Historia miesięczna'!B8:B31)),IFERROR(INDEX('Historia miesięczna'!H8:H31,MAX(0,COUNTA('Historia miesięczna'!B8:B31)-MIN($B$1,COUNTA('Historia miesięczna'!B8:B31)))+6),0),"") | I9: =IF(6<=MIN($B$1,COUNTA('Historia miesięczna'!B8:B31)),IFERROR(INDEX('Historia miesięczna'!I8:I31,MAX(0,COUNTA('Historia miesięczna'!B8:B31)-MIN($B$1,COUNTA('Historia miesięczna'!B8:B31)))+6),0),"") | J9: =IF(6<=MIN($B$1,COUNTA('Historia miesięczna'!B8:B31)),IFERROR(INDEX('Historia miesięczna'!K8:K31,MAX(0,COUNTA('Historia miesięczna'!B8:B31)-MIN($B$1,COUNTA('Historia miesięczna'!B8:B31)))+6),0),"")
A10: 7 | B10: =IF(7<=MIN($B$1,COUNTA('Historia miesięczna'!B8:B31)),INDEX('Historia miesięczna'!B8:B31,MAX(0,COUNTA('Historia miesięczna'!B8:B31)-MIN($B$1,COUNTA('Historia miesięczna'!B8:B31)))+7),"") | C10: =IF(7<=MIN($B$1,COUNTA('Historia miesięczna'!B8:B31)),IFERROR(INDEX('Historia miesięczna'!C8:C31,MAX(0,COUNTA('Historia miesięczna'!B8:B31)-MIN($B$1,COUNTA('Historia miesięczna'!B8:B31)))+7),0),"") | D10: =IF(7<=MIN($B$1,COUNTA('Historia miesięczna'!B8:B31)),IFERROR(INDEX('Historia miesięczna'!F8:F31,MAX(0,COUNTA('Historia miesięczna'!B8:B31)-MIN($B$1,COUNTA('Historia miesięczna'!B8:B31)))+7),0),"") | E10: =IF(7<=MIN($B$1,COUNTA('Historia miesięczna'!B8:B31)),IFERROR(INDEX('Historia miesięczna'!D8:D31,MAX(0,COUNTA('Historia miesięczna'!B8:B31)-MIN($B$1,COUNTA('Historia miesięczna'!B8:B31)))+7),0),"") | F10: =IF(7<=MIN($B$1,COUNTA('Historia miesięczna'!B8:B31)),IFERROR(INDEX('Historia miesięczna'!E8:E31,MAX(0,COUNTA('Historia miesięczna'!B8:B31)-MIN($B$1,COUNTA('Historia miesięczna'!B8:B31)))+7),0),"") | G10: =IF(7<=MIN($B$1,COUNTA('Historia miesięczna'!B8:B31)),IFERROR(INDEX('Historia miesięczna'!G8:G31,MAX(0,COUNTA('Historia miesięczna'!B8:B31)-MIN($B$1,COUNTA('Historia miesięczna'!B8:B31)))+7),0),"") | H10: =IF(7<=MIN($B$1,COUNTA('Historia miesięczna'!B8:B31)),IFERROR(INDEX('Historia miesięczna'!H8:H31,MAX(0,COUNTA('Historia miesięczna'!B8:B31)-MIN($B$1,COUNTA('Historia miesięczna'!B8:B31)))+7),0),"") | I10: =IF(7<=MIN($B$1,COUNTA('Historia miesięczna'!B8:B31)),IFERROR(INDEX('Historia miesięczna'!I8:I31,MAX(0,COUNTA('Historia miesięczna'!B8:B31)-MIN($B$1,COUNTA('Historia miesięczna'!B8:B31)))+7),0),"") | J10: =IF(7<=MIN($B$1,COUNTA('Historia miesięczna'!B8:B31)),IFERROR(INDEX('Historia miesięczna'!K8:K31,MAX(0,COUNTA('Historia miesięczna'!B8:B31)-MIN($B$1,COUNTA('Historia miesięczna'!B8:B31)))+7),0),"")
A11: 8 | B11: =IF(8<=MIN($B$1,COUNTA('Historia miesięczna'!B8:B31)),INDEX('Historia miesięczna'!B8:B31,MAX(0,COUNTA('Historia miesięczna'!B8:B31)-MIN($B$1,COUNTA('Historia miesięczna'!B8:B31)))+8),"") | C11: =IF(8<=MIN($B$1,COUNTA('Historia miesięczna'!B8:B31)),IFERROR(INDEX('Historia miesięczna'!C8:C31,MAX(0,COUNTA('Historia miesięczna'!B8:B31)-MIN($B$1,COUNTA('Historia miesięczna'!B8:B31)))+8),0),"") | D11: =IF(8<=MIN($B$1,COUNTA('Historia miesięczna'!B8:B31)),IFERROR(INDEX('Historia miesięczna'!F8:F31,MAX(0,COUNTA('Historia miesięczna'!B8:B31)-MIN($B$1,COUNTA('Historia miesięczna'!B8:B31)))+8),0),"") | E11: =IF(8<=MIN($B$1,COUNTA('Historia miesięczna'!B8:B31)),IFERROR(INDEX('Historia miesięczna'!D8:D31,MAX(0,COUNTA('Historia miesięczna'!B8:B31)-MIN($B$1,COUNTA('Historia miesięczna'!B8:B31)))+8),0),"") | F11: =IF(8<=MIN($B$1,COUNTA('Historia miesięczna'!B8:B31)),IFERROR(INDEX('Historia miesięczna'!E8:E31,MAX(0,COUNTA('Historia miesięczna'!B8:B31)-MIN($B$1,COUNTA('Historia miesięczna'!B8:B31)))+8),0),"") | G11: =IF(8<=MIN($B$1,COUNTA('Historia miesięczna'!B8:B31)),IFERROR(INDEX('Historia miesięczna'!G8:G31,MAX(0,COUNTA('Historia miesięczna'!B8:B31)-MIN($B$1,COUNTA('Historia miesięczna'!B8:B31)))+8),0),"") | H11: =IF(8<=MIN($B$1,COUNTA('Historia miesięczna'!B8:B31)),IFERROR(INDEX('Historia miesięczna'!H8:H31,MAX(0,COUNTA('Historia miesięczna'!B8:B31)-MIN($B$1,COUNTA('Historia miesięczna'!B8:B31)))+8),0),"") | I11: =IF(8<=MIN($B$1,COUNTA('Historia miesięczna'!B8:B31)),IFERROR(INDEX('Historia miesięczna'!I8:I31,MAX(0,COUNTA('Historia miesięczna'!B8:B31)-MIN($B$1,COUNTA('Historia miesięczna'!B8:B31)))+8),0),"") | J11: =IF(8<=MIN($B$1,COUNTA('Historia miesięczna'!B8:B31)),IFERROR(INDEX('Historia miesięczna'!K8:K31,MAX(0,COUNTA('Historia miesięczna'!B8:B31)-MIN($B$1,COUNTA('Historia miesięczna'!B8:B31)))+8),0),"")
A12: 9 | B12: =IF(9<=MIN($B$1,COUNTA('Historia miesięczna'!B8:B31)),INDEX('Historia miesięczna'!B8:B31,MAX(0,COUNTA('Historia miesięczna'!B8:B31)-MIN($B$1,COUNTA('Historia miesięczna'!B8:B31)))+9),"") | C12: =IF(9<=MIN($B$1,COUNTA('Historia miesięczna'!B8:B31)),IFERROR(INDEX('Historia miesięczna'!C8:C31,MAX(0,COUNTA('Historia miesięczna'!B8:B31)-MIN($B$1,COUNTA('Historia miesięczna'!B8:B31)))+9),0),"") | D12: =IF(9<=MIN($B$1,COUNTA('Historia miesięczna'!B8:B31)),IFERROR(INDEX('Historia miesięczna'!F8:F31,MAX(0,COUNTA('Historia miesięczna'!B8:B31)-MIN($B$1,COUNTA('Historia miesięczna'!B8:B31)))+9),0),"") | E12: =IF(9<=MIN($B$1,COUNTA('Historia miesięczna'!B8:B31)),IFERROR(INDEX('Historia miesięczna'!D8:D31,MAX(0,COUNTA('Historia miesięczna'!B8:B31)-MIN($B$1,COUNTA('Historia miesięczna'!B8:B31)))+9),0),"") | F12: =IF(9<=MIN($B$1,COUNTA('Historia miesięczna'!B8:B31)),IFERROR(INDEX('Historia miesięczna'!E8:E31,MAX(0,COUNTA('Historia miesięczna'!B8:B31)-MIN($B$1,COUNTA('Historia miesięczna'!B8:B31)))+9),0),"") | G12: =IF(9<=MIN($B$1,COUNTA('Historia miesięczna'!B8:B31)),IFERROR(INDEX('Historia miesięczna'!G8:G31,MAX(0,COUNTA('Historia miesięczna'!B8:B31)-MIN($B$1,COUNTA('Historia miesięczna'!B8:B31)))+9),0),"") | H12: =IF(9<=MIN($B$1,COUNTA('Historia miesięczna'!B8:B31)),IFERROR(INDEX('Historia miesięczna'!H8:H31,MAX(0,COUNTA('Historia miesięczna'!B8:B31)-MIN($B$1,COUNTA('Historia miesięczna'!B8:B31)))+9),0),"") | I12: =IF(9<=MIN($B$1,COUNTA('Historia miesięczna'!B8:B31)),IFERROR(INDEX('Historia miesięczna'!I8:I31,MAX(0,COUNTA('Historia miesięczna'!B8:B31)-MIN($B$1,COUNTA('Historia miesięczna'!B8:B31)))+9),0),"") | J12: =IF(9<=MIN($B$1,COUNTA('Historia miesięczna'!B8:B31)),IFERROR(INDEX('Historia miesięczna'!K8:K31,MAX(0,COUNTA('Historia miesięczna'!B8:B31)-MIN($B$1,COUNTA('Historia miesięczna'!B8:B31)))+9),0),"")
A13: 10 | B13: =IF(10<=MIN($B$1,COUNTA('Historia miesięczna'!B8:B31)),INDEX('Historia miesięczna'!B8:B31,MAX(0,COUNTA('Historia miesięczna'!B8:B31)-MIN($B$1,COUNTA('Historia miesięczna'!B8:B31)))+10),"") | C13: =IF(10<=MIN($B$1,COUNTA('Historia miesięczna'!B8:B31)),IFERROR(INDEX('Historia miesięczna'!C8:C31,MAX(0,COUNTA('Historia miesięczna'!B8:B31)-MIN($B$1,COUNTA('Historia miesięczna'!B8:B31)))+10),0),"") | D13: =IF(10<=MIN($B$1,COUNTA('Historia miesięczna'!B8:B31)),IFERROR(INDEX('Historia miesięczna'!F8:F31,MAX(0,COUNTA('Historia miesięczna'!B8:B31)-MIN($B$1,COUNTA('Historia miesięczna'!B8:B31)))+10),0),"") | E13: =IF(10<=MIN($B$1,COUNTA('Historia miesięczna'!B8:B31)),IFERROR(INDEX('Historia miesięczna'!D8:D31,MAX(0,COUNTA('Historia miesięczna'!B8:B31)-MIN($B$1,COUNTA('Historia miesięczna'!B8:B31)))+10),0),"") | F13: =IF(10<=MIN($B$1,COUNTA('Historia miesięczna'!B8:B31)),IFERROR(INDEX('Historia miesięczna'!E8:E31,MAX(0,COUNTA('Historia miesięczna'!B8:B31)-MIN($B$1,COUNTA('Historia miesięczna'!B8:B31)))+10),0),"") | G13: =IF(10<=MIN($B$1,COUNTA('Historia miesięczna'!B8:B31)),IFERROR(INDEX('Historia miesięczna'!G8:G31,MAX(0,COUNTA('Historia miesięczna'!B8:B31)-MIN($B$1,COUNTA('Historia miesięczna'!B8:B31)))+10),0),"") | H13: =IF(10<=MIN($B$1,COUNTA('Historia miesięczna'!B8:B31)),IFERROR(INDEX('Historia miesięczna'!H8:H31,MAX(0,COUNTA('Historia miesięczna'!B8:B31)-MIN($B$1,COUNTA('Historia miesięczna'!B8:B31)))+10),0),"") | I13: =IF(10<=MIN($B$1,COUNTA('Historia miesięczna'!B8:B31)),IFERROR(INDEX('Historia miesięczna'!I8:I31,MAX(0,COUNTA('Historia miesięczna'!B8:B31)-MIN($B$1,COUNTA('Historia miesięczna'!B8:B31)))+10),0),"") | J13: =IF(10<=MIN($B$1,COUNTA('Historia miesięczna'!B8:B31)),IFERROR(INDEX('Historia miesięczna'!K8:K31,MAX(0,COUNTA('Historia miesięczna'!B8:B31)-MIN($B$1,COUNTA('Historia miesięczna'!B8:B31)))+10),0),"")
A14: 11 | B14: =IF(11<=MIN($B$1,COUNTA('Historia miesięczna'!B8:B31)),INDEX('Historia miesięczna'!B8:B31,MAX(0,COUNTA('Historia miesięczna'!B8:B31)-MIN($B$1,COUNTA('Historia miesięczna'!B8:B31)))+11),"") | C14: =IF(11<=MIN($B$1,COUNTA('Historia miesięczna'!B8:B31)),IFERROR(INDEX('Historia miesięczna'!C8:C31,MAX(0,COUNTA('Historia miesięczna'!B8:B31)-MIN($B$1,COUNTA('Historia miesięczna'!B8:B31)))+11),0),"") | D14: =IF(11<=MIN($B$1,COUNTA('Historia miesięczna'!B8:B31)),IFERROR(INDEX('Historia miesięczna'!F8:F31,MAX(0,COUNTA('Historia miesięczna'!B8:B31)-MIN($B$1,COUNTA('Historia miesięczna'!B8:B31)))+11),0),"") | E14: =IF(11<=MIN($B$1,COUNTA('Historia miesięczna'!B8:B31)),IFERROR(INDEX('Historia miesięczna'!D8:D31,MAX(0,COUNTA('Historia miesięczna'!B8:B31)-MIN($B$1,COUNTA('Historia miesięczna'!B8:B31)))+11),0),"") | F14: =IF(11<=MIN($B$1,COUNTA('Historia miesięczna'!B8:B31)),IFERROR(INDEX('Historia miesięczna'!E8:E31,MAX(0,COUNTA('Historia miesięczna'!B8:B31)-MIN($B$1,COUNTA('Historia miesięczna'!B8:B31)))+11),0),"") | G14: =IF(11<=MIN($B$1,COUNTA('Historia miesięczna'!B8:B31)),IFERROR(INDEX('Historia miesięczna'!G8:G31,MAX(0,COUNTA('Historia miesięczna'!B8:B31)-MIN($B$1,COUNTA('Historia miesięczna'!B8:B31)))+11),0),"") | H14: =IF(11<=MIN($B$1,COUNTA('Historia miesięczna'!B8:B31)),IFERROR(INDEX('Historia miesięczna'!H8:H31,MAX(0,COUNTA('Historia miesięczna'!B8:B31)-MIN($B$1,COUNTA('Historia miesięczna'!B8:B31)))+11),0),"") | I14: =IF(11<=MIN($B$1,COUNTA('Historia miesięczna'!B8:B31)),IFERROR(INDEX('Historia miesięczna'!I8:I31,MAX(0,COUNTA('Historia miesięczna'!B8:B31)-MIN($B$1,COUNTA('Historia miesięczna'!B8:B31)))+11),0),"") | J14: =IF(11<=MIN($B$1,COUNTA('Historia miesięczna'!B8:B31)),IFERROR(INDEX('Historia miesięczna'!K8:K31,MAX(0,COUNTA('Historia miesięczna'!B8:B31)-MIN($B$1,COUNTA('Historia miesięczna'!B8:B31)))+11),0),"")
A15: 12 | B15: =IF(12<=MIN($B$1,COUNTA('Historia miesięczna'!B8:B31)),INDEX('Historia miesięczna'!B8:B31,MAX(0,COUNTA('Historia miesięczna'!B8:B31)-MIN($B$1,COUNTA('Historia miesięczna'!B8:B31)))+12),"") | C15: =IF(12<=MIN($B$1,COUNTA('Historia miesięczna'!B8:B31)),IFERROR(INDEX('Historia miesięczna'!C8:C31,MAX(0,COUNTA('Historia miesięczna'!B8:B31)-MIN($B$1,COUNTA('Historia miesięczna'!B8:B31)))+12),0),"") | D15: =IF(12<=MIN($B$1,COUNTA('Historia miesięczna'!B8:B31)),IFERROR(INDEX('Historia miesięczna'!F8:F31,MAX(0,COUNTA('Historia miesięczna'!B8:B31)-MIN($B$1,COUNTA('Historia miesięczna'!B8:B31)))+12),0),"") | E15: =IF(12<=MIN($B$1,COUNTA('Historia miesięczna'!B8:B31)),IFERROR(INDEX('Historia miesięczna'!D8:D31,MAX(0,COUNTA('Historia miesięczna'!B8:B31)-MIN($B$1,COUNTA('Historia miesięczna'!B8:B31)))+12),0),"") | F15: =IF(12<=MIN($B$1,COUNTA('Historia miesięczna'!B8:B31)),IFERROR(INDEX('Historia miesięczna'!E8:E31,MAX(0,COUNTA('Historia miesięczna'!B8:B31)-MIN($B$1,COUNTA('Historia miesięczna'!B8:B31)))+12),0),"") | G15: =IF(12<=MIN($B$1,COUNTA('Historia miesięczna'!B8:B31)),IFERROR(INDEX('Historia miesięczna'!G8:G31,MAX(0,COUNTA('Historia miesięczna'!B8:B31)-MIN($B$1,COUNTA('Historia miesięczna'!B8:B31)))+12),0),"") | H15: =IF(12<=MIN($B$1,COUNTA('Historia miesięczna'!B8:B31)),IFERROR(INDEX('Historia miesięczna'!H8:H31,MAX(0,COUNTA('Historia miesięczna'!B8:B31)-MIN($B$1,COUNTA('Historia miesięczna'!B8:B31)))+12),0),"") | I15: =IF(12<=MIN($B$1,COUNTA('Historia miesięczna'!B8:B31)),IFERROR(INDEX('Historia miesięczna'!I8:I31,MAX(0,COUNTA('Historia miesięczna'!B8:B31)-MIN($B$1,COUNTA('Historia miesięczna'!B8:B31)))+12),0),"") | J15: =IF(12<=MIN($B$1,COUNTA('Historia miesięczna'!B8:B31)),IFERROR(INDEX('Historia miesięczna'!K8:K31,MAX(0,COUNTA('Historia miesięczna'!B8:B31)-MIN($B$1,COUNTA('Historia miesięczna'!B8:B31)))+12),0),"")
A16: 13 | B16: =IF(13<=MIN($B$1,COUNTA('Historia miesięczna'!B8:B31)),INDEX('Historia miesięczna'!B8:B31,MAX(0,COUNTA('Historia miesięczna'!B8:B31)-MIN($B$1,COUNTA('Historia miesięczna'!B8:B31)))+13),"") | C16: =IF(13<=MIN($B$1,COUNTA('Historia miesięczna'!B8:B31)),IFERROR(INDEX('Historia miesięczna'!C8:C31,MAX(0,COUNTA('Historia miesięczna'!B8:B31)-MIN($B$1,COUNTA('Historia miesięczna'!B8:B31)))+13),0),"") | D16: =IF(13<=MIN($B$1,COUNTA('Historia miesięczna'!B8:B31)),IFERROR(INDEX('Historia miesięczna'!F8:F31,MAX(0,COUNTA('Historia miesięczna'!B8:B31)-MIN($B$1,COUNTA('Historia miesięczna'!B8:B31)))+13),0),"") | E16: =IF(13<=MIN($B$1,COUNTA('Historia miesięczna'!B8:B31)),IFERROR(INDEX('Historia miesięczna'!D8:D31,MAX(0,COUNTA('Historia miesięczna'!B8:B31)-MIN($B$1,COUNTA('Historia miesięczna'!B8:B31)))+13),0),"") | F16: =IF(13<=MIN($B$1,COUNTA('Historia miesięczna'!B8:B31)),IFERROR(INDEX('Historia miesięczna'!E8:E31,MAX(0,COUNTA('Historia miesięczna'!B8:B31)-MIN($B$1,COUNTA('Historia miesięczna'!B8:B31)))+13),0),"") | G16: =IF(13<=MIN($B$1,COUNTA('Historia miesięczna'!B8:B31)),IFERROR(INDEX('Historia miesięczna'!G8:G31,MAX(0,COUNTA('Historia miesięczna'!B8:B31)-MIN($B$1,COUNTA('Historia miesięczna'!B8:B31)))+13),0),"") | H16: =IF(13<=MIN($B$1,COUNTA('Historia miesięczna'!B8:B31)),IFERROR(INDEX('Historia miesięczna'!H8:H31,MAX(0,COUNTA('Historia miesięczna'!B8:B31)-MIN($B$1,COUNTA('Historia miesięczna'!B8:B31)))+13),0),"") | I16: =IF(13<=MIN($B$1,COUNTA('Historia miesięczna'!B8:B31)),IFERROR(INDEX('Historia miesięczna'!I8:I31,MAX(0,COUNTA('Historia miesięczna'!B8:B31)-MIN($B$1,COUNTA('Historia miesięczna'!B8:B31)))+13),0),"") | J16: =IF(13<=MIN($B$1,COUNTA('Historia miesięczna'!B8:B31)),IFERROR(INDEX('Historia miesięczna'!K8:K31,MAX(0,COUNTA('Historia miesięczna'!B8:B31)-MIN($B$1,COUNTA('Historia miesięczna'!B8:B31)))+13),0),"")
A17: 14 | B17: =IF(14<=MIN($B$1,COUNTA('Historia miesięczna'!B8:B31)),INDEX('Historia miesięczna'!B8:B31,MAX(0,COUNTA('Historia miesięczna'!B8:B31)-MIN($B$1,COUNTA('Historia miesięczna'!B8:B31)))+14),"") | C17: =IF(14<=MIN($B$1,COUNTA('Historia miesięczna'!B8:B31)),IFERROR(INDEX('Historia miesięczna'!C8:C31,MAX(0,COUNTA('Historia miesięczna'!B8:B31)-MIN($B$1,COUNTA('Historia miesięczna'!B8:B31)))+14),0),"") | D17: =IF(14<=MIN($B$1,COUNTA('Historia miesięczna'!B8:B31)),IFERROR(INDEX('Historia miesięczna'!F8:F31,MAX(0,COUNTA('Historia miesięczna'!B8:B31)-MIN($B$1,COUNTA('Historia miesięczna'!B8:B31)))+14),0),"") | E17: =IF(14<=MIN($B$1,COUNTA('Historia miesięczna'!B8:B31)),IFERROR(INDEX('Historia miesięczna'!D8:D31,MAX(0,COUNTA('Historia miesięczna'!B8:B31)-MIN($B$1,COUNTA('Historia miesięczna'!B8:B31)))+14),0),"") | F17: =IF(14<=MIN($B$1,COUNTA('Historia miesięczna'!B8:B31)),IFERROR(INDEX('Historia miesięczna'!E8:E31,MAX(0,COUNTA('Historia miesięczna'!B8:B31)-MIN($B$1,COUNTA('Historia miesięczna'!B8:B31)))+14),0),"") | G17: =IF(14<=MIN($B$1,COUNTA('Historia miesięczna'!B8:B31)),IFERROR(INDEX('Historia miesięczna'!G8:G31,MAX(0,COUNTA('Historia miesięczna'!B8:B31)-MIN($B$1,COUNTA('Historia miesięczna'!B8:B31)))+14),0),"") | H17: =IF(14<=MIN($B$1,COUNTA('Historia miesięczna'!B8:B31)),IFERROR(INDEX('Historia miesięczna'!H8:H31,MAX(0,COUNTA('Historia miesięczna'!B8:B31)-MIN($B$1,COUNTA('Historia miesięczna'!B8:B31)))+14),0),"") | I17: =IF(14<=MIN($B$1,COUNTA('Historia miesięczna'!B8:B31)),IFERROR(INDEX('Historia miesięczna'!I8:I31,MAX(0,COUNTA('Historia miesięczna'!B8:B31)-MIN($B$1,COUNTA('Historia miesięczna'!B8:B31)))+14),0),"") | J17: =IF(14<=MIN($B$1,COUNTA('Historia miesięczna'!B8:B31)),IFERROR(INDEX('Historia miesięczna'!K8:K31,MAX(0,COUNTA('Historia miesięczna'!B8:B31)-MIN($B$1,COUNTA('Historia miesięczna'!B8:B31)))+14),0),"")
A18: 15 | B18: =IF(15<=MIN($B$1,COUNTA('Historia miesięczna'!B8:B31)),INDEX('Historia miesięczna'!B8:B31,MAX(0,COUNTA('Historia miesięczna'!B8:B31)-MIN($B$1,COUNTA('Historia miesięczna'!B8:B31)))+15),"") | C18: =IF(15<=MIN($B$1,COUNTA('Historia miesięczna'!B8:B31)),IFERROR(INDEX('Historia miesięczna'!C8:C31,MAX(0,COUNTA('Historia miesięczna'!B8:B31)-MIN($B$1,COUNTA('Historia miesięczna'!B8:B31)))+15),0),"") | D18: =IF(15<=MIN($B$1,COUNTA('Historia miesięczna'!B8:B31)),IFERROR(INDEX('Historia miesięczna'!F8:F31,MAX(0,COUNTA('Historia miesięczna'!B8:B31)-MIN($B$1,COUNTA('Historia miesięczna'!B8:B31)))+15),0),"") | E18: =IF(15<=MIN($B$1,COUNTA('Historia miesięczna'!B8:B31)),IFERROR(INDEX('Historia miesięczna'!D8:D31,MAX(0,COUNTA('Historia miesięczna'!B8:B31)-MIN($B$1,COUNTA('Historia miesięczna'!B8:B31)))+15),0),"") | F18: =IF(15<=MIN($B$1,COUNTA('Historia miesięczna'!B8:B31)),IFERROR(INDEX('Historia miesięczna'!E8:E31,MAX(0,COUNTA('Historia miesięczna'!B8:B31)-MIN($B$1,COUNTA('Historia miesięczna'!B8:B31)))+15),0),"") | G18: =IF(15<=MIN($B$1,COUNTA('Historia miesięczna'!B8:B31)),IFERROR(INDEX('Historia miesięczna'!G8:G31,MAX(0,COUNTA('Historia miesięczna'!B8:B31)-MIN($B$1,COUNTA('Historia miesięczna'!B8:B31)))+15),0),"") | H18: =IF(15<=MIN($B$1,COUNTA('Historia miesięczna'!B8:B31)),IFERROR(INDEX('Historia miesięczna'!H8:H31,MAX(0,COUNTA('Historia miesięczna'!B8:B31)-MIN($B$1,COUNTA('Historia miesięczna'!B8:B31)))+15),0),"") | I18: =IF(15<=MIN($B$1,COUNTA('Historia miesięczna'!B8:B31)),IFERROR(INDEX('Historia miesięczna'!I8:I31,MAX(0,COUNTA('Historia miesięczna'!B8:B31)-MIN($B$1,COUNTA('Historia miesięczna'!B8:B31)))+15),0),"") | J18: =IF(15<=MIN($B$1,COUNTA('Historia miesięczna'!B8:B31)),IFERROR(INDEX('Historia miesięczna'!K8:K31,MAX(0,COUNTA('Historia miesięczna'!B8:B31)-MIN($B$1,COUNTA('Historia miesięczna'!B8:B31)))+15),0),"")
A19: 16 | B19: =IF(16<=MIN($B$1,COUNTA('Historia miesięczna'!B8:B31)),INDEX('Historia miesięczna'!B8:B31,MAX(0,COUNTA('Historia miesięczna'!B8:B31)-MIN($B$1,COUNTA('Historia miesięczna'!B8:B31)))+16),"") | C19: =IF(16<=MIN($B$1,COUNTA('Historia miesięczna'!B8:B31)),IFERROR(INDEX('Historia miesięczna'!C8:C31,MAX(0,COUNTA('Historia miesięczna'!B8:B31)-MIN($B$1,COUNTA('Historia miesięczna'!B8:B31)))+16),0),"") | D19: =IF(16<=MIN($B$1,COUNTA('Historia miesięczna'!B8:B31)),IFERROR(INDEX('Historia miesięczna'!F8:F31,MAX(0,COUNTA('Historia miesięczna'!B8:B31)-MIN($B$1,COUNTA('Historia miesięczna'!B8:B31)))+16),0),"") | E19: =IF(16<=MIN($B$1,COUNTA('Historia miesięczna'!B8:B31)),IFERROR(INDEX('Historia miesięczna'!D8:D31,MAX(0,COUNTA('Historia miesięczna'!B8:B31)-MIN($B$1,COUNTA('Historia miesięczna'!B8:B31)))+16),0),"") | F19: =IF(16<=MIN($B$1,COUNTA('Historia miesięczna'!B8:B31)),IFERROR(INDEX('Historia miesięczna'!E8:E31,MAX(0,COUNTA('Historia miesięczna'!B8:B31)-MIN($B$1,COUNTA('Historia miesięczna'!B8:B31)))+16),0),"") | G19: =IF(16<=MIN($B$1,COUNTA('Historia miesięczna'!B8:B31)),IFERROR(INDEX('Historia miesięczna'!G8:G31,MAX(0,COUNTA('Historia miesięczna'!B8:B31)-MIN($B$1,COUNTA('Historia miesięczna'!B8:B31)))+16),0),"") | H19: =IF(16<=MIN($B$1,COUNTA('Historia miesięczna'!B8:B31)),IFERROR(INDEX('Historia miesięczna'!H8:H31,MAX(0,COUNTA('Historia miesięczna'!B8:B31)-MIN($B$1,COUNTA('Historia miesięczna'!B8:B31)))+16),0),"") | I19: =IF(16<=MIN($B$1,COUNTA('Historia miesięczna'!B8:B31)),IFERROR(INDEX('Historia miesięczna'!I8:I31,MAX(0,COUNTA('Historia miesięczna'!B8:B31)-MIN($B$1,COUNTA('Historia miesięczna'!B8:B31)))+16),0),"") | J19: =IF(16<=MIN($B$1,COUNTA('Historia miesięczna'!B8:B31)),IFERROR(INDEX('Historia miesięczna'!K8:K31,MAX(0,COUNTA('Historia miesięczna'!B8:B31)-MIN($B$1,COUNTA('Historia miesięczna'!B8:B31)))+16),0),"")
A20: 17 | B20: =IF(17<=MIN($B$1,COUNTA('Historia miesięczna'!B8:B31)),INDEX('Historia miesięczna'!B8:B31,MAX(0,COUNTA('Historia miesięczna'!B8:B31)-MIN($B$1,COUNTA('Historia miesięczna'!B8:B31)))+17),"") | C20: =IF(17<=MIN($B$1,COUNTA('Historia miesięczna'!B8:B31)),IFERROR(INDEX('Historia miesięczna'!C8:C31,MAX(0,COUNTA('Historia miesięczna'!B8:B31)-MIN($B$1,COUNTA('Historia miesięczna'!B8:B31)))+17),0),"") | D20: =IF(17<=MIN($B$1,COUNTA('Historia miesięczna'!B8:B31)),IFERROR(INDEX('Historia miesięczna'!F8:F31,MAX(0,COUNTA('Historia miesięczna'!B8:B31)-MIN($B$1,COUNTA('Historia miesięczna'!B8:B31)))+17),0),"") | E20: =IF(17<=MIN($B$1,COUNTA('Historia miesięczna'!B8:B31)),IFERROR(INDEX('Historia miesięczna'!D8:D31,MAX(0,COUNTA('Historia miesięczna'!B8:B31)-MIN($B$1,COUNTA('Historia miesięczna'!B8:B31)))+17),0),"") | F20: =IF(17<=MIN($B$1,COUNTA('Historia miesięczna'!B8:B31)),IFERROR(INDEX('Historia miesięczna'!E8:E31,MAX(0,COUNTA('Historia miesięczna'!B8:B31)-MIN($B$1,COUNTA('Historia miesięczna'!B8:B31)))+17),0),"") | G20: =IF(17<=MIN($B$1,COUNTA('Historia miesięczna'!B8:B31)),IFERROR(INDEX('Historia miesięczna'!G8:G31,MAX(0,COUNTA('Historia miesięczna'!B8:B31)-MIN($B$1,COUNTA('Historia miesięczna'!B8:B31)))+17),0),"") | H20: =IF(17<=MIN($B$1,COUNTA('Historia miesięczna'!B8:B31)),IFERROR(INDEX('Historia miesięczna'!H8:H31,MAX(0,COUNTA('Historia miesięczna'!B8:B31)-MIN($B$1,COUNTA('Historia miesięczna'!B8:B31)))+17),0),"") | I20: =IF(17<=MIN($B$1,COUNTA('Historia miesięczna'!B8:B31)),IFERROR(INDEX('Historia miesięczna'!I8:I31,MAX(0,COUNTA('Historia miesięczna'!B8:B31)-MIN($B$1,COUNTA('Historia miesięczna'!B8:B31)))+17),0),"") | J20: =IF(17<=MIN($B$1,COUNTA('Historia miesięczna'!B8:B31)),IFERROR(INDEX('Historia miesięczna'!K8:K31,MAX(0,COUNTA('Historia miesięczna'!B8:B31)-MIN($B$1,COUNTA('Historia miesięczna'!B8:B31)))+17),0),"")
A21: 18 | B21: =IF(18<=MIN($B$1,COUNTA('Historia miesięczna'!B8:B31)),INDEX('Historia miesięczna'!B8:B31,MAX(0,COUNTA('Historia miesięczna'!B8:B31)-MIN($B$1,COUNTA('Historia miesięczna'!B8:B31)))+18),"") | C21: =IF(18<=MIN($B$1,COUNTA('Historia miesięczna'!B8:B31)),IFERROR(INDEX('Historia miesięczna'!C8:C31,MAX(0,COUNTA('Historia miesięczna'!B8:B31)-MIN($B$1,COUNTA('Historia miesięczna'!B8:B31)))+18),0),"") | D21: =IF(18<=MIN($B$1,COUNTA('Historia miesięczna'!B8:B31)),IFERROR(INDEX('Historia miesięczna'!F8:F31,MAX(0,COUNTA('Historia miesięczna'!B8:B31)-MIN($B$1,COUNTA('Historia miesięczna'!B8:B31)))+18),0),"") | E21: =IF(18<=MIN($B$1,COUNTA('Historia miesięczna'!B8:B31)),IFERROR(INDEX('Historia miesięczna'!D8:D31,MAX(0,COUNTA('Historia miesięczna'!B8:B31)-MIN($B$1,COUNTA('Historia miesięczna'!B8:B31)))+18),0),"") | F21: =IF(18<=MIN($B$1,COUNTA('Historia miesięczna'!B8:B31)),IFERROR(INDEX('Historia miesięczna'!E8:E31,MAX(0,COUNTA('Historia miesięczna'!B8:B31)-MIN($B$1,COUNTA('Historia miesięczna'!B8:B31)))+18),0),"") | G21: =IF(18<=MIN($B$1,COUNTA('Historia miesięczna'!B8:B31)),IFERROR(INDEX('Historia miesięczna'!G8:G31,MAX(0,COUNTA('Historia miesięczna'!B8:B31)-MIN($B$1,COUNTA('Historia miesięczna'!B8:B31)))+18),0),"") | H21: =IF(18<=MIN($B$1,COUNTA('Historia miesięczna'!B8:B31)),IFERROR(INDEX('Historia miesięczna'!H8:H31,MAX(0,COUNTA('Historia miesięczna'!B8:B31)-MIN($B$1,COUNTA('Historia miesięczna'!B8:B31)))+18),0),"") | I21: =IF(18<=MIN($B$1,COUNTA('Historia miesięczna'!B8:B31)),IFERROR(INDEX('Historia miesięczna'!I8:I31,MAX(0,COUNTA('Historia miesięczna'!B8:B31)-MIN($B$1,COUNTA('Historia miesięczna'!B8:B31)))+18),0),"") | J21: =IF(18<=MIN($B$1,COUNTA('Historia miesięczna'!B8:B31)),IFERROR(INDEX('Historia miesięczna'!K8:K31,MAX(0,COUNTA('Historia miesięczna'!B8:B31)-MIN($B$1,COUNTA('Historia miesięczna'!B8:B31)))+18),0),"")
A22: 19 | B22: =IF(19<=MIN($B$1,COUNTA('Historia miesięczna'!B8:B31)),INDEX('Historia miesięczna'!B8:B31,MAX(0,COUNTA('Historia miesięczna'!B8:B31)-MIN($B$1,COUNTA('Historia miesięczna'!B8:B31)))+19),"") | C22: =IF(19<=MIN($B$1,COUNTA('Historia miesięczna'!B8:B31)),IFERROR(INDEX('Historia miesięczna'!C8:C31,MAX(0,COUNTA('Historia miesięczna'!B8:B31)-MIN($B$1,COUNTA('Historia miesięczna'!B8:B31)))+19),0),"") | D22: =IF(19<=MIN($B$1,COUNTA('Historia miesięczna'!B8:B31)),IFERROR(INDEX('Historia miesięczna'!F8:F31,MAX(0,COUNTA('Historia miesięczna'!B8:B31)-MIN($B$1,COUNTA('Historia miesięczna'!B8:B31)))+19),0),"") | E22: =IF(19<=MIN($B$1,COUNTA('Historia miesięczna'!B8:B31)),IFERROR(INDEX('Historia miesięczna'!D8:D31,MAX(0,COUNTA('Historia miesięczna'!B8:B31)-MIN($B$1,COUNTA('Historia miesięczna'!B8:B31)))+19),0),"") | F22: =IF(19<=MIN($B$1,COUNTA('Historia miesięczna'!B8:B31)),IFERROR(INDEX('Historia miesięczna'!E8:E31,MAX(0,COUNTA('Historia miesięczna'!B8:B31)-MIN($B$1,COUNTA('Historia miesięczna'!B8:B31)))+19),0),"") | G22: =IF(19<=MIN($B$1,COUNTA('Historia miesięczna'!B8:B31)),IFERROR(INDEX('Historia miesięczna'!G8:G31,MAX(0,COUNTA('Historia miesięczna'!B8:B31)-MIN($B$1,COUNTA('Historia miesięczna'!B8:B31)))+19),0),"") | H22: =IF(19<=MIN($B$1,COUNTA('Historia miesięczna'!B8:B31)),IFERROR(INDEX('Historia miesięczna'!H8:H31,MAX(0,COUNTA('Historia miesięczna'!B8:B31)-MIN($B$1,COUNTA('Historia miesięczna'!B8:B31)))+19),0),"") | I22: =IF(19<=MIN($B$1,COUNTA('Historia miesięczna'!B8:B31)),IFERROR(INDEX('Historia miesięczna'!I8:I31,MAX(0,COUNTA('Historia miesięczna'!B8:B31)-MIN($B$1,COUNTA('Historia miesięczna'!B8:B31)))+19),0),"") | J22: =IF(19<=MIN($B$1,COUNTA('Historia miesięczna'!B8:B31)),IFERROR(INDEX('Historia miesięczna'!K8:K31,MAX(0,COUNTA('Historia miesięczna'!B8:B31)-MIN($B$1,COUNTA('Historia miesięczna'!B8:B31)))+19),0),"")
A23: 20 | B23: =IF(20<=MIN($B$1,COUNTA('Historia miesięczna'!B8:B31)),INDEX('Historia miesięczna'!B8:B31,MAX(0,COUNTA('Historia miesięczna'!B8:B31)-MIN($B$1,COUNTA('Historia miesięczna'!B8:B31)))+20),"") | C23: =IF(20<=MIN($B$1,COUNTA('Historia miesięczna'!B8:B31)),IFERROR(INDEX('Historia miesięczna'!C8:C31,MAX(0,COUNTA('Historia miesięczna'!B8:B31)-MIN($B$1,COUNTA('Historia miesięczna'!B8:B31)))+20),0),"") | D23: =IF(20<=MIN($B$1,COUNTA('Historia miesięczna'!B8:B31)),IFERROR(INDEX('Historia miesięczna'!F8:F31,MAX(0,COUNTA('Historia miesięczna'!B8:B31)-MIN($B$1,COUNTA('Historia miesięczna'!B8:B31)))+20),0),"") | E23: =IF(20<=MIN($B$1,COUNTA('Historia miesięczna'!B8:B31)),IFERROR(INDEX('Historia miesięczna'!D8:D31,MAX(0,COUNTA('Historia miesięczna'!B8:B31)-MIN($B$1,COUNTA('Historia miesięczna'!B8:B31)))+20),0),"") | F23: =IF(20<=MIN($B$1,COUNTA('Historia miesięczna'!B8:B31)),IFERROR(INDEX('Historia miesięczna'!E8:E31,MAX(0,COUNTA('Historia miesięczna'!B8:B31)-MIN($B$1,COUNTA('Historia miesięczna'!B8:B31)))+20),0),"") | G23: =IF(20<=MIN($B$1,COUNTA('Historia miesięczna'!B8:B31)),IFERROR(INDEX('Historia miesięczna'!G8:G31,MAX(0,COUNTA('Historia miesięczna'!B8:B31)-MIN($B$1,COUNTA('Historia miesięczna'!B8:B31)))+20),0),"") | H23: =IF(20<=MIN($B$1,COUNTA('Historia miesięczna'!B8:B31)),IFERROR(INDEX('Historia miesięczna'!H8:H31,MAX(0,COUNTA('Historia miesięczna'!B8:B31)-MIN($B$1,COUNTA('Historia miesięczna'!B8:B31)))+20),0),"") | I23: =IF(20<=MIN($B$1,COUNTA('Historia miesięczna'!B8:B31)),IFERROR(INDEX('Historia miesięczna'!I8:I31,MAX(0,COUNTA('Historia miesięczna'!B8:B31)-MIN($B$1,COUNTA('Historia miesięczna'!B8:B31)))+20),0),"") | J23: =IF(20<=MIN($B$1,COUNTA('Historia miesięczna'!B8:B31)),IFERROR(INDEX('Historia miesięczna'!K8:K31,MAX(0,COUNTA('Historia miesięczna'!B8:B31)-MIN($B$1,COUNTA('Historia miesięczna'!B8:B31)))+20),0),"")
A24: 21 | B24: =IF(21<=MIN($B$1,COUNTA('Historia miesięczna'!B8:B31)),INDEX('Historia miesięczna'!B8:B31,MAX(0,COUNTA('Historia miesięczna'!B8:B31)-MIN($B$1,COUNTA('Historia miesięczna'!B8:B31)))+21),"") | C24: =IF(21<=MIN($B$1,COUNTA('Historia miesięczna'!B8:B31)),IFERROR(INDEX('Historia miesięczna'!C8:C31,MAX(0,COUNTA('Historia miesięczna'!B8:B31)-MIN($B$1,COUNTA('Historia miesięczna'!B8:B31)))+21),0),"") | D24: =IF(21<=MIN($B$1,COUNTA('Historia miesięczna'!B8:B31)),IFERROR(INDEX('Historia miesięczna'!F8:F31,MAX(0,COUNTA('Historia miesięczna'!B8:B31)-MIN($B$1,COUNTA('Historia miesięczna'!B8:B31)))+21),0),"") | E24: =IF(21<=MIN($B$1,COUNTA('Historia miesięczna'!B8:B31)),IFERROR(INDEX('Historia miesięczna'!D8:D31,MAX(0,COUNTA('Historia miesięczna'!B8:B31)-MIN($B$1,COUNTA('Historia miesięczna'!B8:B31)))+21),0),"") | F24: =IF(21<=MIN($B$1,COUNTA('Historia miesięczna'!B8:B31)),IFERROR(INDEX('Historia miesięczna'!E8:E31,MAX(0,COUNTA('Historia miesięczna'!B8:B31)-MIN($B$1,COUNTA('Historia miesięczna'!B8:B31)))+21),0),"") | G24: =IF(21<=MIN($B$1,COUNTA('Historia miesięczna'!B8:B31)),IFERROR(INDEX('Historia miesięczna'!G8:G31,MAX(0,COUNTA('Historia miesięczna'!B8:B31)-MIN($B$1,COUNTA('Historia miesięczna'!B8:B31)))+21),0),"") | H24: =IF(21<=MIN($B$1,COUNTA('Historia miesięczna'!B8:B31)),IFERROR(INDEX('Historia miesięczna'!H8:H31,MAX(0,COUNTA('Historia miesięczna'!B8:B31)-MIN($B$1,COUNTA('Historia miesięczna'!B8:B31)))+21),0),"") | I24: =IF(21<=MIN($B$1,COUNTA('Historia miesięczna'!B8:B31)),IFERROR(INDEX('Historia miesięczna'!I8:I31,MAX(0,COUNTA('Historia miesięczna'!B8:B31)-MIN($B$1,COUNTA('Historia miesięczna'!B8:B31)))+21),0),"") | J24: =IF(21<=MIN($B$1,COUNTA('Historia miesięczna'!B8:B31)),IFERROR(INDEX('Historia miesięczna'!K8:K31,MAX(0,COUNTA('Historia miesięczna'!B8:B31)-MIN($B$1,COUNTA('Historia miesięczna'!B8:B31)))+21),0),"")
A25: 22 | B25: =IF(22<=MIN($B$1,COUNTA('Historia miesięczna'!B8:B31)),INDEX('Historia miesięczna'!B8:B31,MAX(0,COUNTA('Historia miesięczna'!B8:B31)-MIN($B$1,COUNTA('Historia miesięczna'!B8:B31)))+22),"") | C25: =IF(22<=MIN($B$1,COUNTA('Historia miesięczna'!B8:B31)),IFERROR(INDEX('Historia miesięczna'!C8:C31,MAX(0,COUNTA('Historia miesięczna'!B8:B31)-MIN($B$1,COUNTA('Historia miesięczna'!B8:B31)))+22),0),"") | D25: =IF(22<=MIN($B$1,COUNTA('Historia miesięczna'!B8:B31)),IFERROR(INDEX('Historia miesięczna'!F8:F31,MAX(0,COUNTA('Historia miesięczna'!B8:B31)-MIN($B$1,COUNTA('Historia miesięczna'!B8:B31)))+22),0),"") | E25: =IF(22<=MIN($B$1,COUNTA('Historia miesięczna'!B8:B31)),IFERROR(INDEX('Historia miesięczna'!D8:D31,MAX(0,COUNTA('Historia miesięczna'!B8:B31)-MIN($B$1,COUNTA('Historia miesięczna'!B8:B31)))+22),0),"") | F25: =IF(22<=MIN($B$1,COUNTA('Historia miesięczna'!B8:B31)),IFERROR(INDEX('Historia miesięczna'!E8:E31,MAX(0,COUNTA('Historia miesięczna'!B8:B31)-MIN($B$1,COUNTA('Historia miesięczna'!B8:B31)))+22),0),"") | G25: =IF(22<=MIN($B$1,COUNTA('Historia miesięczna'!B8:B31)),IFERROR(INDEX('Historia miesięczna'!G8:G31,MAX(0,COUNTA('Historia miesięczna'!B8:B31)-MIN($B$1,COUNTA('Historia miesięczna'!B8:B31)))+22),0),"") | H25: =IF(22<=MIN($B$1,COUNTA('Historia miesięczna'!B8:B31)),IFERROR(INDEX('Historia miesięczna'!H8:H31,MAX(0,COUNTA('Historia miesięczna'!B8:B31)-MIN($B$1,COUNTA('Historia miesięczna'!B8:B31)))+22),0),"") | I25: =IF(22<=MIN($B$1,COUNTA('Historia miesięczna'!B8:B31)),IFERROR(INDEX('Historia miesięczna'!I8:I31,MAX(0,COUNTA('Historia miesięczna'!B8:B31)-MIN($B$1,COUNTA('Historia miesięczna'!B8:B31)))+22),0),"") | J25: =IF(22<=MIN($B$1,COUNTA('Historia miesięczna'!B8:B31)),IFERROR(INDEX('Historia miesięczna'!K8:K31,MAX(0,COUNTA('Historia miesięczna'!B8:B31)-MIN($B$1,COUNTA('Historia miesięczna'!B8:B31)))+22),0),"")
A26: 23 | B26: =IF(23<=MIN($B$1,COUNTA('Historia miesięczna'!B8:B31)),INDEX('Historia miesięczna'!B8:B31,MAX(0,COUNTA('Historia miesięczna'!B8:B31)-MIN($B$1,COUNTA('Historia miesięczna'!B8:B31)))+23),"") | C26: =IF(23<=MIN($B$1,COUNTA('Historia miesięczna'!B8:B31)),IFERROR(INDEX('Historia miesięczna'!C8:C31,MAX(0,COUNTA('Historia miesięczna'!B8:B31)-MIN($B$1,COUNTA('Historia miesięczna'!B8:B31)))+23),0),"") | D26: =IF(23<=MIN($B$1,COUNTA('Historia miesięczna'!B8:B31)),IFERROR(INDEX('Historia miesięczna'!F8:F31,MAX(0,COUNTA('Historia miesięczna'!B8:B31)-MIN($B$1,COUNTA('Historia miesięczna'!B8:B31)))+23),0),"") | E26: =IF(23<=MIN($B$1,COUNTA('Historia miesięczna'!B8:B31)),IFERROR(INDEX('Historia miesięczna'!D8:D31,MAX(0,COUNTA('Historia miesięczna'!B8:B31)-MIN($B$1,COUNTA('Historia miesięczna'!B8:B31)))+23),0),"") | F26: =IF(23<=MIN($B$1,COUNTA('Historia miesięczna'!B8:B31)),IFERROR(INDEX('Historia miesięczna'!E8:E31,MAX(0,COUNTA('Historia miesięczna'!B8:B31)-MIN($B$1,COUNTA('Historia miesięczna'!B8:B31)))+23),0),"") | G26: =IF(23<=MIN($B$1,COUNTA('Historia miesięczna'!B8:B31)),IFERROR(INDEX('Historia miesięczna'!G8:G31,MAX(0,COUNTA('Historia miesięczna'!B8:B31)-MIN($B$1,COUNTA('Historia miesięczna'!B8:B31)))+23),0),"") | H26: =IF(23<=MIN($B$1,COUNTA('Historia miesięczna'!B8:B31)),IFERROR(INDEX('Historia miesięczna'!H8:H31,MAX(0,COUNTA('Historia miesięczna'!B8:B31)-MIN($B$1,COUNTA('Historia miesięczna'!B8:B31)))+23),0),"") | I26: =IF(23<=MIN($B$1,COUNTA('Historia miesięczna'!B8:B31)),IFERROR(INDEX('Historia miesięczna'!I8:I31,MAX(0,COUNTA('Historia miesięczna'!B8:B31)-MIN($B$1,COUNTA('Historia miesięczna'!B8:B31)))+23),0),"") | J26: =IF(23<=MIN($B$1,COUNTA('Historia miesięczna'!B8:B31)),IFERROR(INDEX('Historia miesięczna'!K8:K31,MAX(0,COUNTA('Historia miesięczna'!B8:B31)-MIN($B$1,COUNTA('Historia miesięczna'!B8:B31)))+23),0),"")
